Workbook

Sheet Crude_Oil_Impact
A1: Country | B1: ISO3 | C1: Crude Oil (Mbbl) | D1: Natural Gas (Mbbl BOE) | E1: Total BOE (Mbbl) | F1: Value @ $10 Change (USD) | G1: Nominal GDP (USD) | H1: Impact (% of GDP) | I1: Data Source
A2: Australia | B2: AUS | C2: 67.4476 | D2: 0 | E2: 67.4476 | F2: 674475814 | G2: 1795492000000 | H2: 0.037565 | I2: WITS
A3: Austria | B3: AUT | C3: 56.2123 | D3: 0.0257 | E3: 56.238 | F3: 562380387 | G3: 523956000000 | H3: 0.107334 | I3: WITS
A4: Bulgaria | B4: BGR | C4: 48.5981 | D4: 0.0019 | E4: 48.6 | F4: 485999961 | G4: 112232000000 | H4: 0.433032 | I4: WITS
A5: Canada | B5: CAN | C5: 170.6321 | D5: 5.7523 | E5: 176.3844 | F5: 1763844244 | G5: 2243637000000 | H5: 0.078615 | I5: WITS
A6: Switzerland | B6: CHE | C6: 18.9607 | D6: 0.0326 | E6: 18.9932 | F6: 189932153 | G6: 938153000000 | H6: 0.020245 | I6: WITS
A7: China | B7: CHN | C7: 4055.1906 | D7: 643.2056 | E7: 4698.3962 | F7: 46983962000 | G7: 18749759000000 | H7: 0.250584 | I7: WITS
A8: Germany | B8: DEU | C8: 575.6762 | D8: 40.2336 | E8: 615.9098 | F8: 6159097740 | G8: 4684182000000 | H8: 0.131487 | I8: WITS
A9: France | B9: FRA | C9: 344.6573 | D9: 173.7473 | E9: 518.4046 | F9: 5184046130 | G9: 3160902000000 | H9: 0.164005 | I9: WITS
A10: India | B10: IND | C10: 1772.0275 | D10: 233.4688 | E10: 2005.4963 | F10: 20054962600 | G10: 3909892000000 | H10: 0.512929 | I10: WITS
A11: Italy | B11: ITA | C11: 399.8141 | D11: 88.9132 | E11: 488.7273 | F11: 4887272770 | G11: 2372059000000 | H11: 0.206035 | I11: WITS
A12: Japan | B12: JPN | C12: 842.6495 | D12: 553.4819 | E12: 1396.1314 | F12: 13961313500 | G12: 4019382000000 | H12: 0.34735 | I12: WITS
A13: South Korea | B13: KOR | C13: 1005.5294 | D13: 389.0704 | E13: 1394.5998 | F13: 13945997600 | G13: 1875388000000 | H13: 0.743633 | I13: WITS
... A30: Vietnam | B30: VNM | C30: 101.2107 | D30: 0 | E30: 101.2107 | F30: 1012107300 | G30: 459472000000 | H30: 0.220276 | I30: UN

Sheet ETF_Timeframes
A1: country_name | B1: country_code | C1: ticker | D1: timeframe | E1: start_date | F1: end_date | G1: etf_return_pct | H1: etf_return_usd_pct | I1: lookup_key | J1: etf_currency
A2: Australia | B2: AUS | C2: SAUS.L | D2: YTD | E2: 46022 | F2: 46098 | G2: 9.926208 | H2: 8.6784885 | I2: Australia|SAUS.L|YTD | J2: GBp
A3: Australia | B3: AUS | C3: SAUS.L | D3: 1 Month | E3: 46070 | F3: 46098 | G3: -0.12975779 | H3: -2.4261624 | I3: Australia|SAUS.L|1 Month | J3: GBp
A4: Australia | B4: AUS | C4: SAUS.L | D4: 3 Months | E4: 46008 | F4: 46098 | G4: 12.278142 | H4: 11.352646 | I4: Australia|SAUS.L|3 Months | J4: GBp
A5: Australia | B5: AUS | C5: SAUS.L | D5: 6 Months | E5: 45917 | F5: 46098 | G5: 10.030975 | H5: 7.2943662 | I5: Australia|SAUS.L|6 Months | J5: GBp
A6: Australia | B6: AUS | C6: SAUS.L | D6: 1 Year | E6: 45733 | F6: 46098 | G6: 21.7827 | H6: 25.39692 | I6: Australia|SAUS.L|1 Year | J6: GBp
A7: Australia | B7: AUS | C7: SAUS.L | D7: 3 Years | E7: 45002 | F7: 46098 | G7: 8.8124411 | H7: 19.628927 | I7: Australia|SAUS.L|3 Years | J7: GBp
A8: Australia | B8: AUS | C8: SAUS.L | D8: 5 Years | E8: 44272 | F8: 46098 | G8: 46.812907 | H8: 40.604717 | I8: Australia|SAUS.L|5 Years | J8: GBp
A9: Australia | B9: AUS | C9: SAUS.L | D9: 10 Years | E9: 42446 | F9: 46098 | G9: 138.47147 | H9: 122.73254 | I9: Australia|SAUS.L|10 Years | J9: GBp
A10: Australia | B10: AUS | C10: SAUS.L | D10: MAX | E10: 40203 | F10: 46098 | G10: 214.69342 | H10: 157.8402 | I10: Australia|SAUS.L|MAX | J10: GBp
A11: Austria | B11: AUT | C11: EWO | D11: YTD | E11: 46022 | F11: 46098 | G11: -1.6915767 | H11: -1.6915767 | I11: Austria|EWO|YTD | J11: USD
A12: Austria | B12: AUT | C12: EWO | D12: 1 Month | E12: 46070 | F12: 46098 | G12: -9.6398062 | H12: -9.6398062 | I12: Austria|EWO|1 Month | J12: USD
A13: Austria | B13: AUT | C13: EWO | D13: 3 Months | E13: 46008 | F13: 46098 | G13: 0.89698364 | H13: 0.89698364 | I13: Austria|EWO|3 Months | J13: USD
... A369: Vietnam | B369: VNM | C369: XFVT.L | D369: MAX | E369: 39818 | F369: 46098 | G369: 20.245659 | H369: 8.7921679 | I369: Vietnam|XFVT.L|MAX | J369: GBp

Sheet Annual
A1: country_name | B1: country_code | C1: ticker | D1: year | E1: etf_return_pct | F1: gdp_real_growth_pct | G1: gdp_nominal_lcu_growth_pct | H1: gdp_nominal_usd_growth_pct | I1: gdp_nominal_usd_minus_etf_growth_pct | J1: lookup_key | K1: country_year_key | L1: etf_currency | M1: etf_return_quote_pct | N1: quote_ccy_vs_usd_pct | O1: quote_ccy_vs_usd_jan1_pct | P1: etf_return_usd_pct | Q1: country_lcu_vs_usd_weo_pct | R1: etf_usd_minus_country_fx_pct | S1: inflation_cpi_pct | T1: usa_inflation_cpi_pct | U1: inflation_cpi_diff | V1: gdp_current_usd
A2: Australia | B2: AUS | C2: SAUS.L | D2: 2015 | E2: -5.4406823 | F2: 2.34 | J2: Australia|SAUS.L|2015 | K2: Australia|2015 | L2: GBp | M2: -5.4406823 | N2: -4.8888559 | O2: -5.4075152 | P2: -10.063551 | S2: 1.485 | T2: 0.121 | U2: 1.364 | V2: 1233914000000
A3: Australia | B3: AUS | C3: SAUS.L | D3: 2016 | E3: 36.157401 | F3: 2.694 | G3: 3.528437 | H3: 2.328444 | I3: -11.191824 | J3: Australia|SAUS.L|2016 | K3: Australia|2016 | L3: GBp | M3: 36.157401 | N3: -16.625709 | O3: -16.211812 | P3: 13.520268 | Q3: -1.1590944 | R3: 14.851506 | S3: 1.277 | T3: 1.267 | U3: 0.01 | V3: 1262645000000
A4: Australia | B4: AUS | C4: SAUS.L | D4: 2017 | E4: 7.5972447 | F4: 2.38 | G4: 6.117511 | H4: 9.381972 | I4: -7.7283627 | J4: Australia|SAUS.L|2017 | K4: Australia|2017 | L4: GBp | M4: 7.5972447 | N4: 8.8413881 | O4: 9.4504359 | P4: 17.110335 | Q4: 3.0762699 | R4: 13.615224 | S4: 1.995 | T4: 2.131 | U4: -0.136 | V4: 1381106000000
A5: Australia | B5: AUS | C5: SAUS.L | D5: 2018 | E5: -6.9164538 | F5: 2.791 | G5: 5.165909 | H5: 2.610372 | I5: 15.191243 | J5: Australia|SAUS.L|2018 | K5: Australia|2018 | L5: GBp | M5: -6.9164538 | N5: -6.0853042 | O5: -5.7563162 | P5: -12.580871 | Q5: -2.4300059 | R5: -10.403675 | S5: 1.933 | T5: 2.439 | U5: -0.506 | V5: 1417158000000
A6: Australia | B6: AUS | C6: SAUS.L | D6: 2019 | E6: 17.457747 | F6: 1.936 | G6: 5.237084 | H6: -2.178233 | I6: -23.093777 | J6: Australia|SAUS.L|2019 | K6: Australia|2019 | L6: GBp | M6: 17.457747 | N6: 2.9438643 | O6: 4.1180316 | P6: 20.915544 | Q6: -7.0462967 | R6: 30.08147 | S6: 1.566 | T6: 1.813 | U6: -0.247 | V6: 1386289000000
A7: Australia | B7: AUS | C7: SAUS.L | D7: 2020 | E7: 4.6928328 | F7: -1.953 | G7: -0.992052 | H7: -1.704118 | I7: -9.3023845 | J7: Australia|SAUS.L|2020 | K7: Australia|2020 | L7: GBp | M7: 4.6928328 | N7: 2.7751984 | O7: 3.0944746 | P7: 7.5982665 | Q7: -0.71920087 | R7: 8.3777201 | S7: 0.89 | T7: 1.253 | U7: -0.363 | V7: 1362665000000
A8: Australia | B8: AUS | C8: SAUS.L | D8: 2021 | E8: 46.780977 | F8: 5.418 | G8: 11.597189 | H8: 21.514679 | I8: -23.391581 | J8: Australia|SAUS.L|2021 | K8: Australia|2021 | L8: GBp | M8: 46.780977 | N8: -1.2772205 | O8: -1.1023431 | P8: 44.90626 | Q8: 8.886864 | R8: 33.079653 | S8: 2.82 | T8: 4.679 | U8: -1.859 | V8: 1655838000000
A9: Australia | B9: AUS | C9: SAUS.L | D9: 2022 | E9: -7.3073181 | F9: 4.132 | G9: 12.723343 | H9: 4.203008 | I9: 21.559183 | J9: Australia|SAUS.L|2022 | K9: Australia|2022 | L9: GBp | M9: -7.3073181 | N9: -10.841047 | O9: -10.367729 | P9: -17.356175 | Q9: -7.558625 | R9: -10.598664 | S9: 6.657 | T9: 7.993 | U9: -1.336 | V9: 1725433000000
A10: Australia | B10: AUS | C10: SAUS.L | D10: 2023 | E10: 15.337351 | F10: 2.066 | G10: 5.55426 | H10: 0.978189 | I10: -20.198727 | J10: Australia|SAUS.L|2023 | K10: Australia|2023 | L10: GBp | M10: 15.337351 | N10: 5.0630307 | O10: 5.030131 | P10: 21.176916 | Q10: -4.3352781 | R10: 26.668341 | S10: 5.594 | T10: 4.128 | U10: 1.466 | V10: 1742311000000
A11: Australia | B11: AUS | C11: SAUS.L | D11: 2024 | E11: -18.614941 | F11: 1.023 | G11: 3.792081 | H11: 3.052325 | I11: 22.823792 | J11: Australia|SAUS.L|2024 | K11: Australia|2024 | L11: GBp | M11: -18.614941 | N11: -1.4210535 | O11: -1.6555391 | P11: -19.771467 | Q11: -0.71272876 | R11: -19.19555 | S11: 3.197 | T11: 2.952 | U11: 0.245 | V11: 1795492000000
A12: Australia | B12: AUS | C12: SAUS.L | D12: 2025 | E12: 4.2173158 | F12: 1.809 | G12: 4.803761 | H12: 1.894523 | I12: -10.214055 | J12: Australia|SAUS.L|2025 | K12: Australia|2025 | L12: GBp | M12: 4.2173158 | N12: 7.5719296 | O12: 7.6233774 | P12: 12.108578 | Q12: -2.7758914 | R12: 15.309442 | S12: 2.576 | T12: 2.715 | U12: -0.139 | V12: 1829508000000
A13: Australia | B13: AUS | C13: SAUS.L | D13: 2026 | E13: 10.425634 | F13: 2.149 | G13: 5.21892 | H13: 6.489122 | I13: -2.1252198 | J13: Australia|SAUS.L|2026 | K13: Australia|2026 | L13: GBp | M13: 10.425634 | N13: -1.6402821 | P13: 8.6143418 | Q13: 1.2071988 | R13: 7.3187906 | S13: 3.024 | T13: 2.435 | U13: 0.589 | V13: 1948227000000
A14: Australia | B14: AUS | C14: SAUS.L | D14: 2027 | F14: 2.153 | G14: 4.462846 | H14: 4.507996 | J14: Australia|SAUS.L|2027 | K14: Australia|2027 | L14: GBp | Q14: 0.043221438 | S14: 2.612 | T14: 2.185 | U14: 0.427 | V14: 2036053000000
A15: Australia | B15: AUS | C15: SAUS.L | D15: 2028 | F15: 2.225 | G15: 4.426395 | H15: 4.71304 | J15: Australia|SAUS.L|2028 | K15: Australia|2028 | L15: GBp | Q15: 0.27449505 | S15: 2.544 | T15: 2.206 | U15: 0.338 | V15: 2132013000000
A16: Australia | B16: AUS | C16: SAUS.L | D16: 2029 | F16: 2.248 | G16: 4.430086 | H16: 4.520282 | J16: Australia|SAUS.L|2029 | K16: Australia|2029 | L16: GBp | Q16: 0.086369819 | S16: 2.526 | T16: 2.203 | U16: 0.323 | V16: 2228386000000
A17: Austria | B17: AUT | C17: EWO | D17: 2015 | E17: 3.3813507 | F17: 1.303 | J17: Austria|EWO|2015 | K17: Austria|2015 | L17: USD | M17: 3.3813507 | N17: 0 | O17: 0 | P17: 3.3813507 | S17: 0.81 | T17: 0.121 | U17: 0.689 | V17: 379584000000
A18: Austria | B18: AUT | C18: EWO | D18: 2016 | E18: 9.1748425 | F18: 2.117 | G18: 3.97037 | H18: 3.686931 | I18: -5.4879115 | J18: Austria|EWO|2016 | K18: Austria|2016 | L18: USD | M18: 9.1748425 | N18: 0 | O18: 0 | P18: 9.1748425 | Q18: -0.27261507 | R18: 9.4732832 | S18: 0.973 | T18: 1.267 | U18: -0.294 | V18: 393579000000
A19: Austria | B19: AUT | C19: EWO | D19: 2017 | E19: 50.19609 | F19: 2.272 | G19: 3.269641 | H19: 5.38672 | I19: -44.80937 | J19: Austria|EWO|2017 | K19: Austria|2017 | L19: USD | M19: 50.19609 | N19: 0 | O19: 0 | P19: 50.19609 | Q19: 2.0500504 | R19: 47.178849 | S19: 2.228 | T19: 2.131 | U19: 0.097 | V19: 414780000000
A20: Austria | B20: AUT | C20: EWO | D20: 2018 | E20: -24.171691 | F20: 2.484 | G20: 4.339564 | H20: 9.163171 | I20: 33.334862 | J20: Austria|EWO|2018 | K20: Austria|2018 | L20: USD | M20: -24.171691 | N20: 0 | O20: 0 | P20: -24.171691 | Q20: 4.6229897 | R20: -27.522327 | S20: 2.122 | T20: 2.439 | U20: -0.317 | V20: 452787000000
A21: Austria | B21: AUT | C21: EWO | D21: 2019 | E21: 17.17948 | F21: 1.755 | G21: 3.254669 | H21: -2.154214 | I21: -19.333694 | J21: Austria|EWO|2019 | K21: Austria|2019 | L21: USD | M21: 17.17948 | N21: 0 | O21: 0 | P21: 17.17948 | Q21: -5.238391 | R21: 23.657123 | S21: 1.493 | T21: 1.813 | U21: -0.32 | V21: 443033000000
A22: Austria | B22: AUT | C22: EWO | D22: 2020 | E22: -4.9541929 | F22: -6.318 | G22: -3.888989 | H22: -2.027614 | I22: 2.9265789 | J22: Austria|EWO|2020 | K22: Austria|2020 | L22: USD | M22: -4.9541929 | N22: 0 | O22: 0 | P22: -4.9541929 | Q22: 1.9366921 | R22: -6.7599653 | S22: 1.392 | T22: 1.253 | U22: 0.139 | V22: 434050000000
A23: Austria | B23: AUT | C23: EWO | D23: 2021 | E23: 30.056737 | F23: 4.795 | G23: 6.813772 | H23: 10.767423 | I23: -19.289314 | J23: Austria|EWO|2021 | K23: Austria|2021 | L23: USD | M23: 30.056737 | N23: 0 | O23: 0 | P23: 30.056737 | Q23: 3.7014436 | R23: 25.414587 | S23: 2.76 | T23: 4.679 | U23: -1.919 | V23: 480786000000
A24: Austria | B24: AUT | C24: EWO | D24: 2022 | E24: -22.068245 | F24: 5.278 | G24: 10.283533 | H24: -1.797265 | I24: 20.27098 | J24: Austria|EWO|2022 | K24: Austria|2022 | L24: USD | M24: -22.068245 | N24: 0 | O24: 0 | P24: -22.068245 | Q24: -10.954308 | R24: -12.481162 | S24: 8.619 | T24: 7.993 | U24: 0.626 | V24: 472145000000
A25: Austria | B25: AUT | C25: EWO | D25: 2023 | E25: 18.994448 | F25: -0.955 | G25: 5.629376 | H25: 8.405892 | I25: -10.588556 | J25: Austria|EWO|2023 | K25: Austria|2023 | L25: USD | M25: 18.994448 | N25: 0 | O25: 0 | P25: 18.994448 | Q25: 2.6285452 | R25: 15.946736 | S25: 7.712 | T25: 4.128 | U25: 3.584 | V25: 511833000000
A26: Austria | B26: AUT | C26: EWO | D26: 2024 | E26: 5.6270366 | F26: -0.989 | G26: 2.323621 | H26: 2.368546 | I26: -3.2584906 | J26: Austria|EWO|2024 | K26: Austria|2024 | L26: USD | M26: 5.6270366 | N26: 0 | O26: 0 | P26: 5.6270366 | Q26: 0.043905212 | R26: 5.5806812 | S26: 2.918 | T26: 2.952 | U26: -0.034 | V26: 523956000000
A27: Austria | B27: AUT | C27: EWO | D27: 2025 | E27: 76.723253 | F27: 0.27 | G27: 3.565712 | H27: 8.111368 | I27: -68.611885 | J27: Austria|EWO|2025 | K27: Austria|2025 | L27: USD | M27: 76.723253 | N27: 0 | O27: 0 | P27: 76.723253 | Q27: 4.3891511 | R27: 69.292739 | S27: 3.562 | T27: 2.715 | U27: 0.847 | V27: 566456000000
A28: Austria | B28: AUT | C28: EWO | D28: 2026 | E28: -2.5705559 | F28: 0.764 | G28: 3.229582 | H28: 6.66283 | I28: 9.2333859 | J28: Austria|EWO|2026 | K28: Austria|2026 | L28: USD | M28: -2.5705559 | N28: 0 | O28: 0 | P28: -2.5705559 | Q28: 3.325837 | R28: -5.7066007 | S28: 2.328 | T28: 2.435 | U28: -0.107 | V28: 604198000000
A29: Austria | B29: AUT | C29: EWO | D29: 2027 | F29: 1.56 | G29: 3.823947 | H29: 3.555126 | J29: Austria|EWO|2027 | K29: Austria|2027 | L29: USD | Q29: -0.25892006 | S29: 2.169 | T29: 2.185 | U29: -0.016 | V29: 625678000000
A30: Austria | B30: AUT | C30: EWO | D30: 2028 | F30: 1.305 | G30: 3.441796 | H30: 3.259664 | J30: Austria|EWO|2028 | K30: Austria|2028 | L30: USD | Q30: -0.17607212 | S30: 2.067 | T30: 2.206 | U30: -0.139 | V30: 646073000000
A31: Austria | B31: AUT | C31: EWO | D31: 2029 | F31: 0.991 | G31: 3.238426 | H31: 3.135404 | J31: Austria|EWO|2029 | K31: Austria|2029 | L31: USD | Q31: -0.099790014 | S31: 2.067 | T31: 2.203 | U31: -0.136 | V31: 666330000000
A32: Belgium | B32: BEL | C32: EWK | D32: 2015 | E32: 13.666992 | F32: 1.474 | J32: Belgium|EWK|2015 | K32: Belgium|2015 | L32: USD | M32: 13.666992 | N32: 0 | O32: 0 | P32: 13.666992 | S32: 0.623 | T32: 0.121 | U32: 0.502 | V32: 461091000000
A33: Belgium | B33: BEL | C33: EWK | D33: 2016 | E33: -0.63308974 | F33: 1.193 | G33: 3.111388 | H33: 2.830244 | I33: 3.4633337 | J33: Belgium|EWK|2016 | K33: Belgium|2016 | L33: USD | M33: -0.63308974 | N33: 0 | O33: 0 | P33: -0.63308974 | Q33: -0.27266067 | R33: -0.3614145 | S33: 1.772 | T33: 1.267 | U33: 0.505 | V33: 474141000000
A34: Belgium | B34: BEL | C34: EWK | D34: 2017 | E34: 23.557553 | F34: 1.475 | G34: 3.487083 | H34: 5.608458 | I34: -17.949095 | J34: Belgium|EWK|2017 | K34: Belgium|2017 | L34: USD | M34: 23.557553 | N34: 0 | O34: 0 | P34: 23.557553 | Q34: 2.0498937 | R34: 21.075631 | S34: 2.225 | T34: 2.131 | U34: 0.094 | V34: 500733000000
A35: Belgium | B35: BEL | C35: EWK | D35: 2018 | E35: -20.930096 | F35: 1.878 | G35: 3.627359 | H35: 8.418059 | I35: 29.348155 | J35: Belgium|EWK|2018 | K35: Belgium|2018 | L35: USD | M35: -20.930096 | N35: 0 | O35: 0 | P35: -20.930096 | Q35: 4.6230071 | R35: -24.423981 | S35: 2.308 | T35: 2.439 | U35: -0.131 | V35: 542885000000
A36: Belgium | B36: BEL | C36: EWK | D36: 2019 | E36: 26.618746 | F36: 2.443 | G36: 4.342622 | H36: -1.123258 | I36: -27.742004 | J36: Belgium|EWK|2019 | K36: Belgium|2019 | L36: USD | M36: 26.618746 | N36: 0 | O36: 0 | P36: 26.618746 | Q36: -5.2383963 | R36: 33.618197 | S36: 1.25 | T36: 1.813 | U36: -0.563 | V36: 536787000000
A37: Belgium | B37: BEL | C37: EWK | D37: 2020 | E37: -0.9693278 | F37: -4.793 | G37: -3.273778 | H37: -1.400556 | I37: -0.4312282 | J37: Belgium|EWK|2020 | K37: Belgium|2020 | L37: USD | M37: -0.9693278 | N37: 0 | O37: 0 | P37: -0.9693278 | Q37: 1.9366237 | R37: -2.8507434 | S37: 0.424 | T37: 1.253 | U37: -0.829 | V37: 529269000000
A38: Belgium | B38: BEL | C38: EWK | D38: 2021 | E38: 11.60173 | F38: 6.207 | G38: 9.120647 | H38: 13.159849 | I38: 1.5581186 | J38: Belgium|EWK|2021 | K38: Belgium|2021 | L38: USD | M38: 11.60173 | N38: 0 | O38: 0 | P38: 11.60173 | Q38: 3.7015927 | R38: 7.6181451 | S38: 3.217 | T38: 4.679 | U38: -1.462 | V38: 598920000000
A39: Belgium | B39: BEL | C39: EWK | D39: 2022 | E39: -15.131847 | F39: 4.26 | G39: 11.394791 | H39: -0.807954 | I39: 14.323893 | J39: Belgium|EWK|2022 | K39: Belgium|2022 | L39: USD | M39: -15.131847 | N39: 0 | O39: 0 | P39: -15.131847 | Q39: -10.954503 | R39: -4.6912463 | S39: 10.331 | T39: 7.993 | U39: 2.338 | V39: 594081000000
A40: Belgium | B40: BEL | C40: EWK | D40: 2023 | E40: 7.1457365 | F40: 1.202 | G40: 5.763957 | H40: 8.544121 | I40: 1.3983845 | J40: Belgium|EWK|2023 | K40: Belgium|2023 | L40: USD | M40: 7.1457365 | N40: 0 | O40: 0 | P40: 7.1457365 | Q40: 2.6286502 | R40: 4.4013892 | S40: 2.294 | T40: 4.128 | U40: -1.834 | V40: 644840000000
...

Sheet CAGR
A1: country_name | B1: country_code | C1: ticker | D1: as_of_date | E1: horizon | F1: etf_cagr_pct | G1: gdp_real_cagr_pct | H1: gdp_nominal_lcu_cagr_pct | I1: gdp_nominal_usd_cagr_pct | J1: fx_cagr_pct | K1: fx_jan1_cagr_pct | L1: inflation_local_cagr_pct | M1: inflation_usa_cagr_pct | N1: inflation_diff_cagr_pct | O1: gdp_nominal_usd_minus_etf_cagr_pct | P1: lookup_key | Q1: country_horizon_key | R1: etf_currency
A2: Australia | B2: AUS | D2: 46022 | E2: 1Y | G2: 1.809 | H2: 4.803761 | I2: 1.894523 | J2: -2.7758914 | K2: 7.8153444 | L2: 2.576 | M2: 2.715 | N2: -0.139 | P2: Australia||1Y | Q2: Australia|1Y
A3: Australia | B3: AUS | D3: 46022 | E3: 3Y | G3: 1.6316967 | H3: 4.7142093 | I3: 1.9714835 | J3: -2.619249 | K3: -0.71245304 | L3: 3.7808821 | M3: 3.2631562 | N3: 0.51772589 | P3: Australia||3Y | Q3: Australia|3Y
A4: Australia | B4: AUS | D4: 46022 | E4: 5Y | G4: 2.8767657 | H4: 7.6308559 | I4: 6.0691387 | J4: -1.4509938 | K4: -2.8144934 | L4: 4.1558836 | M4: 4.4764173 | N4: -0.32053372 | P4: Australia||5Y | Q4: Australia|5Y
A5: Australia | B5: AUS | D5: 46022 | E5: 10Y | G5: 2.2130551 | H5: 5.6877014 | I5: 4.0171481 | J5: -1.5806507 | K5: -0.84761193 | L5: 2.8352486 | M5: 3.1191525 | N5: -0.28390383 | P5: Australia||10Y | Q5: Australia|10Y
A6: Australia | B6: AUS | C6: SAUS.L | D6: 46022 | E6: 1Y | F6: 12.108578 | G6: 1.809 | H6: 4.803761 | I6: 1.894523 | J6: -2.7758914 | K6: 7.8153444 | L6: 2.576 | M6: 2.715 | N6: -0.139 | O6: -10.214055 | P6: Australia|SAUS.L|1Y | Q6: Australia|1Y | R6: GBp
A7: Australia | B7: AUS | C7: SAUS.L | D7: 46022 | E7: 3Y | F7: 3.4182372 | G7: 1.6316967 | H7: 4.7142093 | I7: 1.9714835 | J7: -2.619249 | K7: -0.71245304 | L7: 3.7808821 | M7: 3.2631562 | N7: 0.51772589 | O7: -1.4467537 | P7: Australia|SAUS.L|3Y | Q7: Australia|3Y | R7: GBp
A8: Australia | B8: AUS | C8: SAUS.L | D8: 46022 | E8: 5Y | F8: 5.9141081 | G8: 2.8767657 | H8: 7.6308559 | I8: 6.0691387 | J8: -1.4509938 | K8: -2.8144934 | L8: 4.1558836 | M8: 4.4764173 | N8: -0.32053372 | O8: 0.15503067 | P8: Australia|SAUS.L|5Y | Q8: Australia|5Y | R8: GBp
A9: Australia | B9: AUS | C9: SAUS.L | D9: 46022 | E9: 10Y | F9: 7.602351 | G9: 2.2130551 | H9: 5.6877014 | I9: 4.0171481 | J9: -1.5806507 | K9: -0.84761193 | L9: 2.8352486 | M9: 3.1191525 | N9: -0.28390383 | O9: -3.585203 | P9: Australia|SAUS.L|10Y | Q9: Australia|10Y | R9: GBp
A10: Austria | B10: AUT | D10: 46022 | E10: 1Y | G10: 0.27 | H10: 3.565712 | I10: 8.111368 | J10: 4.3891511 | K10: 13.510676 | L10: 3.562 | M10: 2.715 | N10: 0.847 | P10: Austria||1Y | Q10: Austria|1Y
A11: Austria | B11: AUT | D11: 46022 | E11: 3Y | G11: -0.5597198 | H11: 3.8306414 | I11: 6.258479 | J11: 2.338267 | K11: 3.1396087 | L11: 4.7093071 | M11: 3.2631562 | N11: 1.4461509 | P11: Austria||3Y | Q11: Austria|3Y
A12: Austria | B12: AUT | D12: 46022 | E12: 5Y | G12: 1.6419624 | H12: 5.6873252 | I12: 5.4691107 | J12: -0.20647166 | K12: -0.71591222 | L12: 5.0841342 | M12: 4.4764173 | N12: 0.60771697 | P12: Austria||5Y | Q12: Austria|5Y
A13: Austria | B13: AUT | D13: 46022 | E13: 10Y | G13: 1.0203336 | H13: 3.8993583 | I13: 4.0844444 | J13: 0.17813987 | K13: 0.79205215 | L13: 3.347981 | M13: 3.1191525 | N13: 0.22882855 | P13: Austria||10Y | Q13: Austria|10Y
A14: Austria | B14: AUT | C14: EWO | D14: 46022 | E14: 1Y | F14: 76.723253 | G14: 0.27 | H14: 3.565712 | I14: 8.111368 | J14: 4.3891511 | K14: 13.510676 | L14: 3.562 | M14: 2.715 | N14: 0.847 | O14: -68.611885 | P14: Austria|EWO|1Y | Q14: Austria|1Y | R14: USD
A15: Austria | B15: AUT | C15: EWO | D15: 46022 | E15: 3Y | F15: 29.207033 | G15: -0.5597198 | H15: 3.8306414 | I15: 6.258479 | J15: 2.338267 | K15: 3.1396087 | L15: 4.7093071 | M15: 3.2631562 | N15: 1.4461509 | O15: -22.948554 | P15: Austria|EWO|3Y | Q15: Austria|3Y | R15: USD
A16: Austria | B16: AUT | C16: EWO | D16: 46022 | E16: 5Y | F16: 17.289225 | G16: 1.6419624 | H16: 5.6873252 | I16: 5.4691107 | J16: -0.20647166 | K16: -0.71591222 | L16: 5.0841342 | M16: 4.4764173 | N16: 0.60771697 | O16: -11.820114 | P16: Austria|EWO|5Y | Q16: Austria|5Y | R16: USD
A17: Austria | B17: AUT | C17: EWO | D17: 46022 | E17: 10Y | F17: 12.503822 | G17: 1.0203336 | H17: 3.8993583 | I17: 4.0844444 | J17: 0.17813987 | K17: 0.79205215 | L17: 3.347981 | M17: 3.1191525 | N17: 0.22882855 | O17: -8.4193778 | P17: Austria|EWO|10Y | Q17: Austria|10Y | R17: USD
A18: Belgium | B18: BEL | D18: 46022 | E18: 1Y | G18: 1.065 | H18: 3.381842 | I18: 7.919592 | J18: 4.3893113 | K18: 13.510676 | L18: 2.571 | M18: 2.715 | N18: -0.144 | P18: Belgium||1Y | Q18: Belgium|1Y
A19: Belgium | B19: BEL | D19: 46022 | E19: 3Y | G19: 1.0953035 | H19: 4.0356288 | I19: 6.4683342 | J19: 2.338339 | K19: 3.1396087 | L19: 3.058437 | M19: 3.2631562 | N19: -0.20471919 | P19: Belgium||3Y | Q19: Belgium|3Y
A20: Belgium | B20: BEL | D20: 46022 | E20: 5Y | G20: 2.728929 | H20: 6.478916 | I20: 6.259096 | J20: -0.20644449 | K20: -0.71591222 | L20: 4.5056783 | M20: 4.4764173 | N20: 0.029261022 | P20: Belgium||5Y | Q20: Belgium|5Y
A21: Belgium | B21: BEL | D21: 46022 | E21: 10Y | G21: 1.5594853 | H21: 4.3275788 | I21: 4.5134152 | J21: 0.17812793 | K21: 0.79205215 | L21: 3.0392529 | M21: 3.1191525 | N21: -0.079899531 | P21: Belgium||10Y | Q21: Belgium|10Y
A22: Belgium | B22: BEL | C22: EWK | D22: 46022 | E22: 1Y | F22: 35.85671 | G22: 1.065 | H22: 3.381842 | I22: 7.919592 | J22: 4.3893113 | K22: 13.510676 | L22: 2.571 | M22: 2.715 | N22: -0.144 | O22: -27.937118 | P22: Belgium|EWK|1Y | Q22: Belgium|1Y | R22: USD
A23: Belgium | B23: BEL | C23: EWK | D23: 46022 | E23: 3Y | F23: 13.257981 | G23: 1.0953035 | H23: 4.0356288 | I23: 6.4683342 | J23: 2.338339 | K23: 3.1396087 | L23: 3.058437 | M23: 3.2631562 | N23: -0.20471919 | O23: -6.7896468 | P23: Belgium|EWK|3Y | Q23: Belgium|3Y | R23: USD
A24: Belgium | B24: BEL | C24: EWK | D24: 46022 | E24: 5Y | F24: 6.9394083 | G24: 2.728929 | H24: 6.478916 | I24: 6.259096 | J24: -0.20644449 | K24: -0.71591222 | L24: 4.5056783 | M24: 4.4764173 | N24: 0.029261022 | O24: -0.68031228 | P24: Belgium|EWK|5Y | Q24: Belgium|5Y | R24: USD
A25: Belgium | B25: BEL | C25: EWK | D25: 46022 | E25: 10Y | F25: 5.7116699 | G25: 1.5594853 | H25: 4.3275788 | I25: 4.5134152 | J25: 0.17812793 | K25: 0.79205215 | L25: 3.0392529 | M25: 3.1191525 | N25: -0.079899531 | O25: -1.1982547 | P25: Belgium|EWK|10Y | Q25: Belgium|10Y | R25: USD
A26: Brazil | B26: BRA | D26: 46022 | E26: 1Y | G26: 2.4 | H26: 7.880595 | I26: 3.555866 | J26: -4.0088115 | K26: 14.192495 | L26: 5.187 | M26: 2.715 | N26: 2.472 | P26: Brazil||1Y | Q26: Brazil|1Y
A27: Brazil | B27: BRA | D27: 46022 | E27: 3Y | G27: 3.0117348 | H27: 7.9227509 | I27: 4.9597227 | J27: -2.7455086 | K27: -1.4187414 | L27: 4.71543 | M27: 3.2631562 | N27: 1.4522737 | P27: Brazil||3Y | Q27: Brazil|3Y
A28: Brazil | B28: BRA | D28: 46022 | E28: 5Y | G28: 3.3606866 | H28: 10.734969 | I28: 8.8629661 | J28: -1.6905254 | K28: -1.2065827 | L28: 6.326579 | M28: 4.4764173 | N28: 1.8501617 | P28: Brazil||5Y | Q28: Brazil|5Y
A29: Brazil | B29: BRA | D29: 46022 | E29: 10Y | G29: 1.4261432 | H29: 7.7690216 | I29: 2.2876178 | J29: -5.0862519 | K29: -3.2859861 | L29: 5.4287729 | M29: 3.1191525 | N29: 2.3096205 | P29: Brazil||10Y | Q29: Brazil|10Y
A30: Brazil | B30: BRA | C30: XMBR.L | D30: 46022 | E30: 1Y | F30: 46.256677 | G30: 2.4 | H30: 7.880595 | I30: 3.555866 | J30: -4.0088115 | K30: 14.192495 | L30: 5.187 | M30: 2.715 | N30: 2.472 | O30: -42.700811 | P30: Brazil|XMBR.L|1Y | Q30: Brazil|1Y | R30: GBp
A31: Brazil | B31: BRA | C31: XMBR.L | D31: 46022 | E31: 3Y | F31: 13.230397 | G31: 3.0117348 | H31: 7.9227509 | I31: 4.9597227 | J31: -2.7455086 | K31: -1.4187414 | L31: 4.71543 | M31: 3.2631562 | N31: 1.4522737 | O31: -8.2706742 | P31: Brazil|XMBR.L|3Y | Q31: Brazil|3Y | R31: GBp
A32: Brazil | B32: BRA | C32: XMBR.L | D32: 46022 | E32: 5Y | F32: 4.9184156 | G32: 3.3606866 | H32: 10.734969 | I32: 8.8629661 | J32: -1.6905254 | K32: -1.2065827 | L32: 6.326579 | M32: 4.4764173 | N32: 1.8501617 | O32: 3.9445504 | P32: Brazil|XMBR.L|5Y | Q32: Brazil|5Y | R32: GBp
A33: Brazil | B33: BRA | C33: XMBR.L | D33: 46022 | E33: 10Y | F33: 10.038 | G33: 1.4261432 | H33: 7.7690216 | I33: 2.2876178 | J33: -5.0862519 | K33: -3.2859861 | L33: 5.4287729 | M33: 3.1191525 | N33: 2.3096205 | O33: -7.7503818 | P33: Brazil|XMBR.L|10Y | Q33: Brazil|10Y | R33: GBp
A34: Canada | B34: CAN | D34: 46022 | E34: 1Y | G34: 1.153 | H34: 3.577136 | I34: 1.781126 | J34: -1.7339833 | K34: 4.8016816 | L34: 1.963 | M34: 2.715 | N34: -0.752 | P34: Canada||1Y | Q34: Canada|1Y
A35: Canada | B35: CAN | D35: 46022 | E35: 3Y | G35: 1.4121668 | H35: 3.7326125 | I35: 1.3984724 | J35: -2.2501509 | K35: -0.45874639 | L35: 2.7453812 | M35: 3.2631562 | N35: -0.51777503 | P35: Canada||3Y | Q35: Canada|3Y
A36: Canada | B36: CAN | D36: 46022 | E36: 5Y | G36: 2.8583192 | H36: 7.4621668 | I36: 6.6420358 | J36: -0.76318134 | K36: -2.0764409 | L36: 3.6703255 | M36: 4.4764173 | N36: -0.80609179 | P36: Canada||5Y | Q36: Canada|5Y
A37: Canada | B37: CAN | D37: 46022 | E37: 10Y | G37: 1.769516 | H37: 4.804148 | I37: 3.9074888 | J37: -0.85555697 | K37: 0.13312944 | L37: 2.6252162 | M37: 3.1191525 | N37: -0.49393623 | P37: Canada||10Y | Q37: Canada|10Y
A38: Canada | B38: CAN | C38: CSCA.L | D38: 46022 | E38: 1Y | F38: 34.384986 | G38: 1.153 | H38: 3.577136 | I38: 1.781126 | J38: -1.7339833 | K38: 4.8016816 | L38: 1.963 | M38: 2.715 | N38: -0.752 | O38: -32.60386 | P38: Canada|CSCA.L|1Y | Q38: Canada|1Y | R38: GBp
A39: Canada | B39: CAN | C39: CSCA.L | D39: 46022 | E39: 3Y | F39: 20.369761 | G39: 1.4121668 | H39: 3.7326125 | I39: 1.3984724 | J39: -2.2501509 | K39: -0.45874639 | L39: 2.7453812 | M39: 3.2631562 | N39: -0.51777503 | O39: -18.971288 | P39: Canada|CSCA.L|3Y | Q39: Canada|3Y | R39: GBp
A40: Canada | B40: CAN | C40: CSCA.L | D40: 46022 | E40: 5Y | F40: 13.58489 | G40: 2.8583192 | H40: 7.4621668 | I40: 6.6420358 | J40: -0.76318134 | K40: -2.0764409 | L40: 3.6703255 | M40: 4.4764173 | N40: -0.80609179 | O40: -6.9428537 | P40: Canada|CSCA.L|5Y | Q40: Canada|5Y | R40: GBp
...

Sheet REER_Data
A1: country_name | B1: bis_code | C1: current_reer | D1: avg_10y_reer | E1: reer_pct_diff
A2: Austria | B2: AT | C2: 107.49 | D2: 100.41504 | E2: 7.045716
A3: Australia | B3: AU | C3: 110.52 | D3: 105.88463 | E3: 4.3777572
A4: Belgium | B4: BE | C4: 104.96 | D4: 99.951074 | E4: 5.0113775
A5: Bulgaria | B5: BG | C5: 116.21 | D5: 102.48223 | E5: 13.395267
A6: Brazil | B6: BR | C6: 109.71 | D6: 116.37752 | E6: -5.729217
A7: Canada | B7: CA | C7: 96.52 | D7: 101.19322 | E7: -4.6181187
A8: Switzerland | B8: CH | C8: 103.82 | D8: 98.925289 | E8: 4.9478862
A9: China | B9: CN | C9: 89.85 | D9: 97.15686 | E9: -7.5206831
A10: Germany | B10: DE | C10: 102.04 | D10: 99.613554 | E10: 2.4358596
A11: Spain | B11: ES | C11: 103.63 | D11: 100.42397 | E11: 3.1924979
A12: France | B12: FR | C12: 96.52 | D12: 98.14719 | E12: -1.657908
A13: United Kingdom | B13: GB | C13: 111.8 | D13: 103.82058 | E13: 7.6857802
... A33: South Africa | B33: ZA | C33: 112.14 | D33: 106.08165 | E33: 5.7110225

Sheet Lists
A1: country_name | B1: ticker | C1: country_for_default | D1: default_ticker | E1: region | F1: country_name | G1: ticker | H1: ticker_display | J1: ticker | K1: ticker_display | L1: ticker_exchange | M1: ticker_currency
A2: Australia | B2: CJPU.L | C2: Australia | D2: SAUS.L | E2: Oceania | F2: Australia | G2: SAUS.L | H2: SAUS.L | J2: CJPU.L | K2: CJPU.L | L2: London Stock Exchange | M2: USD
A3: Austria | B3: CSCA.L | C3: Austria | D3: EWO* | E3: Europe | F3: Austria | G3: EWO | H3: EWO* | J3: CSCA.L | K3: CSCA.L | L3: London Stock Exchange | M3: GBp
A4: Belgium | B4: CSKR.L | C4: Belgium | D4: EWK* | E4: Europe | F4: Belgium | G4: EWK | H4: EWK* | J4: CSKR.L | K4: CSKR.L | L4: London Stock Exchange | M4: USD
A5: Brazil | B5: CSPX.L | C5: Brazil | D5: XMBR.L | E5: Latin America | F5: Brazil | G5: XMBR.L | H5: XMBR.L | J5: CSPX.L | K5: CSPX.L | L5: London Stock Exchange | M5: USD
A6: Canada | B6: CSUK.L | C6: Canada | D6: CSCA.L | E6: North America | F6: Canada | G6: CSCA.L | H6: CSCA.L | J6: CSUK.L | K6: CSUK.L | L6: London Stock Exchange | M6: GBp
A7: China | B7: CSUS.L | C7: China | D7: IASH.L | E7: Asia | F7: China | G7: IASH.L | H7: IASH.L | J7: CSUS.L | K7: CSUS.L | L7: London Stock Exchange | M7: USD
A8: France | B8: CSW.PA | C8: France | D8: ISFR.L | E8: Europe | F8: France | G8: ISFR.L | H8: ISFR.L | J8: CSW.PA | K8: CSW.PA | L8: PAR | M8: EUR
A9: Germany | B9: CSWG.L | C9: Germany | D9: EXS1.DE | E9: Europe | F9: Germany | G9: EXS1.DE | H9: EXS1.DE | J9: CSWG.L | K9: CSWG.L | L9: London Stock Exchange | M9: GBp
A10: Greece | B10: CUKX.L | C10: Greece | D10: GREK* | E10: Europe | F10: Germany | G10: XDAX.L | H10: XDAX.L | J10: CUKX.L | K10: CUKX.L | L10: London Stock Exchange | M10: GBp
A11: Hong Kong | B11: EWD | C11: Hong Kong | D11: EWH* | E11: Asia | F11: Greece | G11: GREK | H11: GREK* | J11: EWD | K11: EWD* | L11: NYSE Arca | M11: USD
A12: India | B12: EWH | C12: India | D12: LYINR.SW | E12: Asia | F12: Hong Kong | G12: EWH | H12: EWH* | J12: EWH | K12: EWH* | L12: NYSE Arca | M12: USD
... A34: Vietnam | B34: XCX3.L | C34: Vietnam | D34: XFVT.L | E34: Asia | F34: Taiwan | G34: XMTW.L | H34: XMTW.L | J34: XCX3.L | K34: XCX3.L | L34: London Stock Exchange | M34: GBp
B35: XCX4.L | E35: Other | F35: Thailand | G35: XCX4.L | H35: XCX4.L | J35: XCX4.L | K35: XCX4.L | L35: London Stock Exchange | M35: GBp
B36: XDAX.L | E36: Other | F36: Turkey | G36: TUR | H36: TUR* | J36: XDAX.L | K36: XDAX.L | L36: London Stock Exchange | M36: GBp
B37: XESP.DE | E37: Other | F37: Turkey | G37: TURL.L | H37: TURL.L | J37: XESP.DE | K37: XESP.DE | L37: GER | M37: EUR
B38: XFVT.L | E38: Other | F38: United Kingdom | G38: CSUK.L | H38: CSUK.L | J38: XFVT.L | K38: XFVT.L | L38: London Stock Exchange | M38: GBp
B39: XMBR.L | E39: Other | F39: United Kingdom | G39: CUKX.L | H39: CUKX.L | J39: XMBR.L | K39: XMBR.L | L39: London Stock Exchange | M39: GBp
B40: XMEX.L | E40: Other | F40: United States | G40: CSPX.L | H40: CSPX.L | J40: XMEX.L | K40: XMEX.L | L40: London Stock Exchange | M40: GBp
B41: XMTW.L | E41: Other | F41: United States | G41: CSUS.L | H41: CSUS.L | J41: XMTW.L | K41: XMTW.L | L41: London Stock Exchange | M41: GBp
B42: XPHG.L | E42: Other | F42: Vietnam | G42: XFVT.L | H42: XFVT.L | J42: XPHG.L | K42: XPHG.L | L42: London Stock Exchange | M42: GBp

Sheet Comparing Countries
A1: Country Disconnect Dashboard (As of Mar 18, 2026)
A2: Horizon (choice between 1Y, 3Y, 5Y, 10Y) | B2: 10Y | D2: Region Filter (using hidden reference columns) | E2: (asia, europe, etc.) | G2: Sort by (choice of GDP size) | H2: nGDP
A4: Country | B4: ETF Ticker | C4: nGDP (USD) CAGR (%) | D4: ETF Return (USD) CAGR (%) | E4: MSCI Index Retrun (USD) CAGR (%) | F4: Macro Gap (%) | G4: Projected Growth (2026-28) CAGR (%) | H4: Impact of $10 Oil Price change relative to GDP (%) | I4: REER Index | J4: REER vs 10Y | K4: Futures rate for USD/LCU 2 years out (%) | L4: GDP Metrics | M4: nGDP (USD) 2025 | N4: nGDP (LCU) CAGR (%) | O4: rGDP (LCU) CAGR (%) | P4: Exchange Rate Metrics | Q4: FX CAGR % | R4: FX Jan 1st CAGR % | S4: USD/LCU spot rate as of "today" | T4: Futures rate for USD/LCU (2 years out from "today") | U4: Inflation Metrics | V4: Inf. Diff CAGR % | W4: Differential | X4: Currency Gap % | Y4: Country Info | Z4: Region | AA4: Local Currency Unit (LCU) | AB4: ETF Info | AC4: Exchange name for ETF ticker | AD4: ETF ticker currency
A5: Australia | B5: SAUS.L | C5: =IFERROR(1*INDEX(CAGR!$I:$I, MATCH($A5&"|"&$B$2, CAGR!$Q:$Q, 0)), NA()) | D5: =IFERROR(1*INDEX(CAGR!$F:$F, MATCH($A5&"|"&$B5&"|"&$B$2, CAGR!$P:$P, 0)), NA()) | E5: =IFERROR(INDEX(MSCI!$B:$E, MATCH("Australia", MSCI!$A:$A, 0), MATCH($B$2, MSCI!$B$1:$E$1, 0)), NA()) | F5: =IF(AND(ISNUMBER(C5),ISNUMBER(D5)),C5-D5,NA()) | G5: =IFERROR((( (1+INDEX(Annual!$H:$H, MATCH($A5&"|2026", Annual!$K:$K, 0))/100)*(1+INDEX(Annual!$H:$H, MATCH($A5&"|2027", Annual!$K:$K, 0))/100)*(1+INDEX(Annual!$H:$H, MATCH($A5&"|2028", Annual!$K:$K, 0))/100) )^(1/3)-1)*100, NA()) | H5: =IFERROR(INDEX(Crude_Oil_Impact!$H:$H, MATCH($A5, Crude_Oil_Impact!$A:$A, 0)), NA()) | I5: =IFERROR(INDEX(REER_Data!$C:$C, MATCH($A5, REER_Data!$A:$A, 0)), NA()) | J5: =IFERROR(INDEX(REER_Data!$E:$E, MATCH($A5, REER_Data!$A:$A, 0)) / 100, NA()) | K5: NA() | M5: 1829508000000 | N5: =IFERROR(1*INDEX(CAGR!$H:$H, MATCH($A5&"|"&$B$2, CAGR!$Q:$Q, 0)), NA()) | O5: =IFERROR(1*INDEX(CAGR!$G:$G, MATCH($A5&"|"&$B$2, CAGR!$Q:$Q, 0)), NA()) | Q5: =IFERROR(1*INDEX(CAGR!$J:$J, MATCH($A5&"|"&$B$2, CAGR!$Q:$Q, 0)), NA()) | R5: =IFERROR(1*INDEX(CAGR!$K:$K, MATCH($A5&"|"&$B$2, CAGR!$Q:$Q, 0)), NA()) | T5: NA() | V5: =IFERROR(1*INDEX(CAGR!$N:$N, MATCH($A5&"|"&$B$2, CAGR!$Q:$Q, 0)), NA()) | X5: =IF(AND(ISNUMBER(Q5),ISNUMBER(V5)),Q5+V5,NA()) | Z5: Oceania | AA5: AUD | AC5: =IFERROR(INDEX(Lists!$J$2:$J$42, MATCH($B5, Lists!$I$2:$I$42, 0)),"") | AD5: =IFERROR(INDEX(Lists!$K$2:$K$42, MATCH($B5, Lists!$I$2:$I$42, 0)),"")
A6: Austria | B6: EWO | C6: =IFERROR(1*INDEX(CAGR!$I:$I, MATCH($A6&"|"&$B$2, CAGR!$Q:$Q, 0)), NA()) | D6: =IFERROR(1*INDEX(CAGR!$F:$F, MATCH($A6&"|"&$B6&"|"&$B$2, CAGR!$P:$P, 0)), NA()) | E6: =IFERROR(INDEX(MSCI!$B:$E, MATCH("Austria", MSCI!$A:$A, 0), MATCH($B$2, MSCI!$B$1:$E$1, 0)), NA()) | F6: =IF(AND(ISNUMBER(C6),ISNUMBER(D6)),C6-D6,NA()) | G6: =IFERROR((( (1+INDEX(Annual!$H:$H, MATCH($A6&"|2026", Annual!$K:$K, 0))/100)*(1+INDEX(Annual!$H:$H, MATCH($A6&"|2027", Annual!$K:$K, 0))/100)*(1+INDEX(Annual!$H:$H, MATCH($A6&"|2028", Annual!$K:$K, 0))/100) )^(1/3)-1)*100, NA()) | H6: =IFERROR(INDEX(Crude_Oil_Impact!$H:$H, MATCH($A6, Crude_Oil_Impact!$A:$A, 0)), NA()) | I6: =IFERROR(INDEX(REER_Data!$C:$C, MATCH($A6, REER_Data!$A:$A, 0)), NA()) | J6: =IFERROR(INDEX(REER_Data!$E:$E, MATCH($A6, REER_Data!$A:$A, 0)) / 100, NA()) | K6: NA() | M6: 566456000000 | N6: =IFERROR(1*INDEX(CAGR!$H:$H, MATCH($A6&"|"&$B$2, CAGR!$Q:$Q, 0)), NA()) | O6: =IFERROR(1*INDEX(CAGR!$G:$G, MATCH($A6&"|"&$B$2, CAGR!$Q:$Q, 0)), NA()) | Q6: =IFERROR(1*INDEX(CAGR!$J:$J, MATCH($A6&"|"&$B$2, CAGR!$Q:$Q, 0)), NA()) | R6: =IFERROR(1*INDEX(CAGR!$K:$K, MATCH($A6&"|"&$B$2, CAGR!$Q:$Q, 0)), NA()) | S6: 1 | T6: NA() | V6: =IFERROR(1*INDEX(CAGR!$N:$N, MATCH($A6&"|"&$B$2, CAGR!$Q:$Q, 0)), NA()) | X6: =IF(AND(ISNUMBER(Q6),ISNUMBER(V6)),Q6+V6,NA()) | Z6: Europe | AA6: EUR | AC6: =IFERROR(INDEX(Lists!$J$2:$J$42, MATCH($B6, Lists!$I$2:$I$42, 0)),"") | AD6: =IFERROR(INDEX(Lists!$K$2:$K$42, MATCH($B6, Lists!$I$2:$I$42, 0)),"")
A7: Belgium | B7: EWK | C7: =IFERROR(1*INDEX(CAGR!$I:$I, MATCH($A7&"|"&$B$2, CAGR!$Q:$Q, 0)), NA()) | D7: =IFERROR(1*INDEX(CAGR!$F:$F, MATCH($A7&"|"&$B7&"|"&$B$2, CAGR!$P:$P, 0)), NA()) | E7: =IFERROR(INDEX(MSCI!$B:$E, MATCH("Belgium", MSCI!$A:$A, 0), MATCH($B$2, MSCI!$B$1:$E$1, 0)), NA()) | F7: =IF(AND(ISNUMBER(C7),ISNUMBER(D7)),C7-D7,NA()) | G7: =IFERROR((( (1+INDEX(Annual!$H:$H, MATCH($A7&"|2026", Annual!$K:$K, 0))/100)*(1+INDEX(Annual!$H:$H, MATCH($A7&"|2027", Annual!$K:$K, 0))/100)*(1+INDEX(Annual!$H:$H, MATCH($A7&"|2028", Annual!$K:$K, 0))/100) )^(1/3)-1)*100, NA()) | H7: =IFERROR(INDEX(Crude_Oil_Impact!$H:$H, MATCH($A7, Crude_Oil_Impact!$A:$A, 0)), NA()) | I7: =IFERROR(INDEX(REER_Data!$C:$C, MATCH($A7, REER_Data!$A:$A, 0)), NA()) | J7: =IFERROR(INDEX(REER_Data!$E:$E, MATCH($A7, REER_Data!$A:$A, 0)) / 100, NA()) | K7: NA() | M7: 716980000000 | N7: =IFERROR(1*INDEX(CAGR!$H:$H, MATCH($A7&"|"&$B$2, CAGR!$Q:$Q, 0)), NA()) | O7: =IFERROR(1*INDEX(CAGR!$G:$G, MATCH($A7&"|"&$B$2, CAGR!$Q:$Q, 0)), NA()) | Q7: =IFERROR(1*INDEX(CAGR!$J:$J, MATCH($A7&"|"&$B$2, CAGR!$Q:$Q, 0)), NA()) | R7: =IFERROR(1*INDEX(CAGR!$K:$K, MATCH($A7&"|"&$B$2, CAGR!$Q:$Q, 0)), NA()) | S7: 1 | T7: NA() | V7: =IFERROR(1*INDEX(CAGR!$N:$N, MATCH($A7&"|"&$B$2, CAGR!$Q:$Q, 0)), NA()) | X7: =IF(AND(ISNUMBER(Q7),ISNUMBER(V7)),Q7+V7,NA()) | Z7: Europe | AA7: EUR | AC7: =IFERROR(INDEX(Lists!$J$2:$J$42, MATCH($B7, Lists!$I$2:$I$42, 0)),"") | AD7: =IFERROR(INDEX(Lists!$K$2:$K$42, MATCH($B7, Lists!$I$2:$I$42, 0)),"")
A8: Brazil | B8: XMBR.L | C8: =IFERROR(1*INDEX(CAGR!$I:$I, MATCH($A8&"|"&$B$2, CAGR!$Q:$Q, 0)), NA()) | D8: =IFERROR(1*INDEX(CAGR!$F:$F, MATCH($A8&"|"&$B8&"|"&$B$2, CAGR!$P:$P, 0)), NA()) | E8: =IFERROR(INDEX(MSCI!$B:$E, MATCH("Brazil", MSCI!$A:$A, 0), MATCH($B$2, MSCI!$B$1:$E$1, 0)), NA()) | F8: =IF(AND(ISNUMBER(C8),ISNUMBER(D8)),C8-D8,NA()) | G8: =IFERROR((( (1+INDEX(Annual!$H:$H, MATCH($A8&"|2026", Annual!$K:$K, 0))/100)*(1+INDEX(Annual!$H:$H, MATCH($A8&"|2027", Annual!$K:$K, 0))/100)*(1+INDEX(Annual!$H:$H, MATCH($A8&"|2028", Annual!$K:$K, 0))/100) )^(1/3)-1)*100, NA()) | H8: =IFERROR(INDEX(Crude_Oil_Impact!$H:$H, MATCH($A8, Crude_Oil_Impact!$A:$A, 0)), NA()) | I8: =IFERROR(INDEX(REER_Data!$C:$C, MATCH($A8, REER_Data!$A:$A, 0)), NA()) | J8: =IFERROR(INDEX(REER_Data!$E:$E, MATCH($A8, REER_Data!$A:$A, 0)) / 100, NA()) | K8: NA() | M8: 2256910000000 | N8: =IFERROR(1*INDEX(CAGR!$H:$H, MATCH($A8&"|"&$B$2, CAGR!$Q:$Q, 0)), NA()) | O8: =IFERROR(1*INDEX(CAGR!$G:$G, MATCH($A8&"|"&$B$2, CAGR!$Q:$Q, 0)), NA()) | Q8: =IFERROR(1*INDEX(CAGR!$J:$J, MATCH($A8&"|"&$B$2, CAGR!$Q:$Q, 0)), NA()) | R8: =IFERROR(1*INDEX(CAGR!$K:$K, MATCH($A8&"|"&$B$2, CAGR!$Q:$Q, 0)), NA()) | T8: NA() | V8: =IFERROR(1*INDEX(CAGR!$N:$N, MATCH($A8&"|"&$B$2, CAGR!$Q:$Q, 0)), NA()) | X8: =IF(AND(ISNUMBER(Q8),ISNUMBER(V8)),Q8+V8,NA()) | Z8: Latin America | AA8: BRL | AC8: =IFERROR(INDEX(Lists!$J$2:$J$42, MATCH($B8, Lists!$I$2:$I$42, 0)),"") | AD8: =IFERROR(INDEX(Lists!$K$2:$K$42, MATCH($B8, Lists!$I$2:$I$42, 0)),"")
A9: Canada | B9: CSCA.L | C9: =IFERROR(1*INDEX(CAGR!$I:$I, MATCH($A9&"|"&$B$2, CAGR!$Q:$Q, 0)), NA()) | D9: =IFERROR(1*INDEX(CAGR!$F:$F, MATCH($A9&"|"&$B9&"|"&$B$2, CAGR!$P:$P, 0)), NA()) | E9: =IFERROR(INDEX(MSCI!$B:$E, MATCH("Canada", MSCI!$A:$A, 0), MATCH($B$2, MSCI!$B$1:$E$1, 0)), NA()) | F9: =IF(AND(ISNUMBER(C9),ISNUMBER(D9)),C9-D9,NA()) | G9: =IFERROR((( (1+INDEX(Annual!$H:$H, MATCH($A9&"|2026", Annual!$K:$K, 0))/100)*(1+INDEX(Annual!$H:$H, MATCH($A9&"|2027", Annual!$K:$K, 0))/100)*(1+INDEX(Annual!$H:$H, MATCH($A9&"|2028", Annual!$K:$K, 0))/100) )^(1/3)-1)*100, NA()) | H9: =IFERROR(INDEX(Crude_Oil_Impact!$H:$H, MATCH($A9, Crude_Oil_Impact!$A:$A, 0)), NA()) | I9: =IFERROR(INDEX(REER_Data!$C:$C, MATCH($A9, REER_Data!$A:$A, 0)), NA()) | J9: =IFERROR(INDEX(REER_Data!$E:$E, MATCH($A9, REER_Data!$A:$A, 0)) / 100, NA()) | K9: NA() | M9: 2283599000000 | N9: =IFERROR(1*INDEX(CAGR!$H:$H, MATCH($A9&"|"&$B$2, CAGR!$Q:$Q, 0)), NA()) | O9: =IFERROR(1*INDEX(CAGR!$G:$G, MATCH($A9&"|"&$B$2, CAGR!$Q:$Q, 0)), NA()) | Q9: =IFERROR(1*INDEX(CAGR!$J:$J, MATCH($A9&"|"&$B$2, CAGR!$Q:$Q, 0)), NA()) | R9: =IFERROR(1*INDEX(CAGR!$K:$K, MATCH($A9&"|"&$B$2, CAGR!$Q:$Q, 0)), NA()) | T9: NA() | V9: =IFERROR(1*INDEX(CAGR!$N:$N, MATCH($A9&"|"&$B$2, CAGR!$Q:$Q, 0)), NA()) | X9: =IF(AND(ISNUMBER(Q9),ISNUMBER(V9)),Q9+V9,NA()) | Z9: North America | AA9: CAD | AC9: =IFERROR(INDEX(Lists!$J$2:$J$42, MATCH($B9, Lists!$I$2:$I$42, 0)),"") | AD9: =IFERROR(INDEX(Lists!$K$2:$K$42, MATCH($B9, Lists!$I$2:$I$42, 0)),"")
A10: China | B10: IASH.L | C10: =IFERROR(1*INDEX(CAGR!$I:$I, MATCH($A10&"|"&$B$2, CAGR!$Q:$Q, 0)), NA()) | D10: =IFERROR(1*INDEX(CAGR!$F:$F, MATCH($A10&"|"&$B10&"|"&$B$2, CAGR!$P:$P, 0)), NA()) | E10: =IFERROR(INDEX(MSCI!$B:$E, MATCH("China", MSCI!$A:$A, 0), MATCH($B$2, MSCI!$B$1:$E$1, 0)), NA()) | F10: =IF(AND(ISNUMBER(C10),ISNUMBER(D10)),C10-D10,NA()) | G10: =IFERROR((( (1+INDEX(Annual!$H:$H, MATCH($A10&"|2026", Annual!$K:$K, 0))/100)*(1+INDEX(Annual!$H:$H, MATCH($A10&"|2027", Annual!$K:$K, 0))/100)*(1+INDEX(Annual!$H:$H, MATCH($A10&"|2028", Annual!$K:$K, 0))/100) )^(1/3)-1)*100, NA()) | H10: =IFERROR(INDEX(Crude_Oil_Impact!$H:$H, MATCH($A10, Crude_Oil_Impact!$A:$A, 0)), NA()) | I10: =IFERROR(INDEX(REER_Data!$C:$C, MATCH($A10, REER_Data!$A:$A, 0)), NA()) | J10: =IFERROR(INDEX(REER_Data!$E:$E, MATCH($A10, REER_Data!$A:$A, 0)) / 100, NA()) | K10: NA() | M10: 19398577000000 | N10: =IFERROR(1*INDEX(CAGR!$H:$H, MATCH($A10&"|"&$B$2, CAGR!$Q:$Q, 0)), NA()) | O10: =IFERROR(1*INDEX(CAGR!$G:$G, MATCH($A10&"|"&$B$2, CAGR!$Q:$Q, 0)), NA()) | Q10: =IFERROR(1*INDEX(CAGR!$J:$J, MATCH($A10&"|"&$B$2, CAGR!$Q:$Q, 0)), NA()) | R10: =IFERROR(1*INDEX(CAGR!$K:$K, MATCH($A10&"|"&$B$2, CAGR!$Q:$Q, 0)), NA()) | T10: NA() | V10: =IFERROR(1*INDEX(CAGR!$N:$N, MATCH($A10&"|"&$B$2, CAGR!$Q:$Q, 0)), NA()) | X10: =IF(AND(ISNUMBER(Q10),ISNUMBER(V10)),Q10+V10,NA()) | Z10: Asia | AA10: CNY | AC10: =IFERROR(INDEX(Lists!$J$2:$J$42, MATCH($B10, Lists!$I$2:$I$42, 0)),"") | AD10: =IFERROR(INDEX(Lists!$K$2:$K$42, MATCH($B10, Lists!$I$2:$I$42, 0)),"")
A11: France | B11: ISFR.L | C11: =IFERROR(1*INDEX(CAGR!$I:$I, MATCH($A11&"|"&$B$2, CAGR!$Q:$Q, 0)), NA()) | D11: =IFERROR(1*INDEX(CAGR!$F:$F, MATCH($A11&"|"&$B11&"|"&$B$2, CAGR!$P:$P, 0)), NA()) | E11: =IFERROR(INDEX(MSCI!$B:$E, MATCH("France", MSCI!$A:$A, 0), MATCH($B$2, MSCI!$B$1:$E$1, 0)), NA()) | F11: =IF(AND(ISNUMBER(C11),ISNUMBER(D11)),C11-D11,NA()) | G11: =IFERROR((( (1+INDEX(Annual!$H:$H, MATCH($A11&"|2026", Annual!$K:$K, 0))/100)*(1+INDEX(Annual!$H:$H, MATCH($A11&"|2027", Annual!$K:$K, 0))/100)*(1+INDEX(Annual!$H:$H, MATCH($A11&"|2028", Annual!$K:$K, 0))/100) )^(1/3)-1)*100, NA()) | H11: =IFERROR(INDEX(Crude_Oil_Impact!$H:$H, MATCH($A11, Crude_Oil_Impact!$A:$A, 0)), NA()) | I11: =IFERROR(INDEX(REER_Data!$C:$C, MATCH($A11, REER_Data!$A:$A, 0)), NA()) | J11: =IFERROR(INDEX(REER_Data!$E:$E, MATCH($A11, REER_Data!$A:$A, 0)) / 100, NA()) | K11: NA() | M11: 3361557000000 | N11: =IFERROR(1*INDEX(CAGR!$H:$H, MATCH($A11&"|"&$B$2, CAGR!$Q:$Q, 0)), NA()) | O11: =IFERROR(1*INDEX(CAGR!$G:$G, MATCH($A11&"|"&$B$2, CAGR!$Q:$Q, 0)), NA()) | Q11: =IFERROR(1*INDEX(CAGR!$J:$J, MATCH($A11&"|"&$B$2, CAGR!$Q:$Q, 0)), NA()) | R11: =IFERROR(1*INDEX(CAGR!$K:$K, MATCH($A11&"|"&$B$2, CAGR!$Q:$Q, 0)), NA()) | T11: NA() | V11: =IFERROR(1*INDEX(CAGR!$N:$N, MATCH($A11&"|"&$B$2, CAGR!$Q:$Q, 0)), NA()) | X11: =IF(AND(ISNUMBER(Q11),ISNUMBER(V11)),Q11+V11,NA()) | Z11: Europe | AA11: EUR | AC11: =IFERROR(INDEX(Lists!$J$2:$J$42, MATCH($B11, Lists!$I$2:$I$42, 0)),"") | AD11: =IFERROR(INDEX(Lists!$K$2:$K$42, MATCH($B11, Lists!$I$2:$I$42, 0)),"")
A12: Germany | B12: EXS1.DE | C12: =IFERROR(1*INDEX(CAGR!$I:$I, MATCH($A12&"|"&$B$2, CAGR!$Q:$Q, 0)), NA()) | D12: =IFERROR(1*INDEX(CAGR!$F:$F, MATCH($A12&"|"&$B12&"|"&$B$2, CAGR!$P:$P, 0)), NA()) | E12: =IFERROR(INDEX(MSCI!$B:$E, MATCH("Germany", MSCI!$A:$A, 0), MATCH($B$2, MSCI!$B$1:$E$1, 0)), NA()) | F12: =IF(AND(ISNUMBER(C12),ISNUMBER(D12)),C12-D12,NA()) | G12: =IFERROR((( (1+INDEX(Annual!$H:$H, MATCH($A12&"|2026", Annual!$K:$K, 0))/100)*(1+INDEX(Annual!$H:$H, MATCH($A12&"|2027", Annual!$K:$K, 0))/100)*(1+INDEX(Annual!$H:$H, MATCH($A12&"|2028", Annual!$K:$K, 0))/100) )^(1/3)-1)*100, NA()) | H12: =IFERROR(INDEX(Crude_Oil_Impact!$H:$H, MATCH($A12, Crude_Oil_Impact!$A:$A, 0)), NA()) | I12: =IFERROR(INDEX(REER_Data!$C:$C, MATCH($A12, REER_Data!$A:$A, 0)), NA()) | J12: =IFERROR(INDEX(REER_Data!$E:$E, MATCH($A12, REER_Data!$A:$A, 0)) / 100, NA()) | K12: NA() | M12: 5013574000000 | N12: =IFERROR(1*INDEX(CAGR!$H:$H, MATCH($A12&"|"&$B$2, CAGR!$Q:$Q, 0)), NA()) | O12: =IFERROR(1*INDEX(CAGR!$G:$G, MATCH($A12&"|"&$B$2, CAGR!$Q:$Q, 0)), NA()) | Q12: =IFERROR(1*INDEX(CAGR!$J:$J, MATCH($A12&"|"&$B$2, CAGR!$Q:$Q, 0)), NA()) | R12: =IFERROR(1*INDEX(CAGR!$K:$K, MATCH($A12&"|"&$B$2, CAGR!$Q:$Q, 0)), NA()) | S12: 0.87279998 | T12: NA() | V12: =IFERROR(1*INDEX(CAGR!$N:$N, MATCH($A12&"|"&$B$2, CAGR!$Q:$Q, 0)), NA()) | X12: =IF(AND(ISNUMBER(Q12),ISNUMBER(V12)),Q12+V12,NA()) | Z12: Europe | AA12: EUR | AC12: =IFERROR(INDEX(Lists!$J$2:$J$42, MATCH($B12, Lists!$I$2:$I$42, 0)),"") | AD12: =IFERROR(INDEX(Lists!$K$2:$K$42, MATCH($B12, Lists!$I$2:$I$42, 0)),"")
A13: Greece | B13: GREK | C13: =IFERROR(1*INDEX(CAGR!$I:$I, MATCH($A13&"|"&$B$2, CAGR!$Q:$Q, 0)), NA()) | D13: =IFERROR(1*INDEX(CAGR!$F:$F, MATCH($A13&"|"&$B13&"|"&$B$2, CAGR!$P:$P, 0)), NA()) | E13: =IFERROR(INDEX(MSCI!$B:$E, MATCH("Greece", MSCI!$A:$A, 0), MATCH($B$2, MSCI!$B$1:$E$1, 0)), NA()) | F13: =IF(AND(ISNUMBER(C13),ISNUMBER(D13)),C13-D13,NA()) | G13: =IFERROR((( (1+INDEX(Annual!$H:$H, MATCH($A13&"|2026", Annual!$K:$K, 0))/100)*(1+INDEX(Annual!$H:$H, MATCH($A13&"|2027", Annual!$K:$K, 0))/100)*(1+INDEX(Annual!$H:$H, MATCH($A13&"|2028", Annual!$K:$K, 0))/100) )^(1/3)-1)*100, NA()) | H13: =IFERROR(INDEX(Crude_Oil_Impact!$H:$H, MATCH($A13, Crude_Oil_Impact!$A:$A, 0)), NA()) | I13: =IFERROR(INDEX(REER_Data!$C:$C, MATCH($A13, REER_Data!$A:$A, 0)), NA()) | J13: =IFERROR(INDEX(REER_Data!$E:$E, MATCH($A13, REER_Data!$A:$A, 0)) / 100, NA()) | K13: NA() | M13: 282019000000 | N13: =IFERROR(1*INDEX(CAGR!$H:$H, MATCH($A13&"|"&$B$2, CAGR!$Q:$Q, 0)), NA()) | O13: =IFERROR(1*INDEX(CAGR!$G:$G, MATCH($A13&"|"&$B$2, CAGR!$Q:$Q, 0)), NA()) | Q13: =IFERROR(1*INDEX(CAGR!$J:$J, MATCH($A13&"|"&$B$2, CAGR!$Q:$Q, 0)), NA()) | R13: =IFERROR(1*INDEX(CAGR!$K:$K, MATCH($A13&"|"&$B$2, CAGR!$Q:$Q, 0)), NA()) | S13: 1 | T13: NA() | V13: =IFERROR(1*INDEX(CAGR!$N:$N, MATCH($A13&"|"&$B$2, CAGR!$Q:$Q, 0)), NA()) | X13: =IF(AND(ISNUMBER(Q13),ISNUMBER(V13)),Q13+V13,NA()) | Z13: Europe | AA13: EUR | AC13: =IFERROR(INDEX(Lists!$J$2:$J$42, MATCH($B13, Lists!$I$2:$I$42, 0)),"") | AD13: =IFERROR(INDEX(Lists!$K$2:$K$42, MATCH($B13, Lists!$I$2:$I$42, 0)),"")
A14: Hong Kong | B14: EWH | C14: =IFERROR(1*INDEX(CAGR!$I:$I, MATCH($A14&"|"&$B$2, CAGR!$Q:$Q, 0)), NA()) | D14: =IFERROR(1*INDEX(CAGR!$F:$F, MATCH($A14&"|"&$B14&"|"&$B$2, CAGR!$P:$P, 0)), NA()) | E14: =IFERROR(INDEX(MSCI!$B:$E, MATCH("Hong Kong", MSCI!$A:$A, 0), MATCH($B$2, MSCI!$B$1:$E$1, 0)), NA()) | F14: =IF(AND(ISNUMBER(C14),ISNUMBER(D14)),C14-D14,NA()) | G14: =IFERROR((( (1+INDEX(Annual!$H:$H, MATCH($A14&"|2026", Annual!$K:$K, 0))/100)*(1+INDEX(Annual!$H:$H, MATCH($A14&"|2027", Annual!$K:$K, 0))/100)*(1+INDEX(Annual!$H:$H, MATCH($A14&"|2028", Annual!$K:$K, 0))/100) )^(1/3)-1)*100, NA()) | H14: =IFERROR(INDEX(Crude_Oil_Impact!$H:$H, MATCH($A14, Crude_Oil_Impact!$A:$A, 0)), NA()) | I14: =IFERROR(INDEX(REER_Data!$C:$C, MATCH($A14, REER_Data!$A:$A, 0)), NA()) | J14: =IFERROR(INDEX(REER_Data!$E:$E, MATCH($A14, REER_Data!$A:$A, 0)) / 100, NA()) | K14: NA() | M14: 428233000000 | N14: =IFERROR(1*INDEX(CAGR!$H:$H, MATCH($A14&"|"&$B$2, CAGR!$Q:$Q, 0)), NA()) | O14: =IFERROR(1*INDEX(CAGR!$G:$G, MATCH($A14&"|"&$B$2, CAGR!$Q:$Q, 0)), NA()) | Q14: =IFERROR(1*INDEX(CAGR!$J:$J, MATCH($A14&"|"&$B$2, CAGR!$Q:$Q, 0)), NA()) | R14: =IFERROR(1*INDEX(CAGR!$K:$K, MATCH($A14&"|"&$B$2, CAGR!$Q:$Q, 0)), NA()) | S14: 1 | T14: NA() | V14: =IFERROR(1*INDEX(CAGR!$N:$N, MATCH($A14&"|"&$B$2, CAGR!$Q:$Q, 0)), NA()) | X14: =IF(AND(ISNUMBER(Q14),ISNUMBER(V14)),Q14+V14,NA()) | Z14: Asia | AA14: HKD | AC14: =IFERROR(INDEX(Lists!$J$2:$J$42, MATCH($B14, Lists!$I$2:$I$42, 0)),"") | AD14: =IFERROR(INDEX(Lists!$K$2:$K$42, MATCH($B14, Lists!$I$2:$I$42, 0)),"")
A15: India | B15: LYINR.SW | C15: =IFERROR(1*INDEX(CAGR!$I:$I, MATCH($A15&"|"&$B$2, CAGR!$Q:$Q, 0)), NA()) | D15: =IFERROR(1*INDEX(CAGR!$F:$F, MATCH($A15&"|"&$B15&"|"&$B$2, CAGR!$P:$P, 0)), NA()) | E15: =IFERROR(INDEX(MSCI!$B:$E, MATCH("India", MSCI!$A:$A, 0), MATCH($B$2, MSCI!$B$1:$E$1, 0)), NA()) | F15: =IF(AND(ISNUMBER(C15),ISNUMBER(D15)),C15-D15,NA()) | G15: =IFERROR((( (1+INDEX(Annual!$H:$H, MATCH($A15&"|2026", Annual!$K:$K, 0))/100)*(1+INDEX(Annual!$H:$H, MATCH($A15&"|2027", Annual!$K:$K, 0))/100)*(1+INDEX(Annual!$H:$H, MATCH($A15&"|2028", Annual!$K:$K, 0))/100) )^(1/3)-1)*100, NA()) | H15: =IFERROR(INDEX(Crude_Oil_Impact!$H:$H, MATCH($A15, Crude_Oil_Impact!$A:$A, 0)), NA()) | I15: =IFERROR(INDEX(REER_Data!$C:$C, MATCH($A15, REER_Data!$A:$A, 0)), NA()) | J15: =IFERROR(INDEX(REER_Data!$E:$E, MATCH($A15, REER_Data!$A:$A, 0)) / 100, NA()) | K15: NA() | M15: 4125213000000 | N15: =IFERROR(1*INDEX(CAGR!$H:$H, MATCH($A15&"|"&$B$2, CAGR!$Q:$Q, 0)), NA()) | O15: =IFERROR(1*INDEX(CAGR!$G:$G, MATCH($A15&"|"&$B$2, CAGR!$Q:$Q, 0)), NA()) | Q15: =IFERROR(1*INDEX(CAGR!$J:$J, MATCH($A15&"|"&$B$2, CAGR!$Q:$Q, 0)), NA()) | R15: =IFERROR(1*INDEX(CAGR!$K:$K, MATCH($A15&"|"&$B$2, CAGR!$Q:$Q, 0)), NA()) | S15: 1 | T15: NA() | V15: =IFERROR(1*INDEX(CAGR!$N:$N, MATCH($A15&"|"&$B$2, CAGR!$Q:$Q, 0)), NA()) | X15: =IF(AND(ISNUMBER(Q15),ISNUMBER(V15)),Q15+V15,NA()) | Z15: Asia | AA15: INR | AC15: =IFERROR(INDEX(Lists!$J$2:$J$42, MATCH($B15, Lists!$I$2:$I$42, 0)),"") | AD15: =IFERROR(INDEX(Lists!$K$2:$K$42, MATCH($B15, Lists!$I$2:$I$42, 0)),"")
A16: Indonesia | B16: INDO.PA | C16: =IFERROR(1*INDEX(CAGR!$I:$I, MATCH($A16&"|"&$B$2, CAGR!$Q:$Q, 0)), NA()) | D16: =IFERROR(1*INDEX(CAGR!$F:$F, MATCH($A16&"|"&$B16&"|"&$B$2, CAGR!$P:$P, 0)), NA()) | E16: =IFERROR(INDEX(MSCI!$B:$E, MATCH("Indonesia", MSCI!$A:$A, 0), MATCH($B$2, MSCI!$B$1:$E$1, 0)), NA()) | F16: =IF(AND(ISNUMBER(C16),ISNUMBER(D16)),C16-D16,NA()) | G16: =IFERROR((( (1+INDEX(Annual!$H:$H, MATCH($A16&"|2026", Annual!$K:$K, 0))/100)*(1+INDEX(Annual!$H:$H, MATCH($A16&"|2027", Annual!$K:$K, 0))/100)*(1+INDEX(Annual!$H:$H, MATCH($A16&"|2028", Annual!$K:$K, 0))/100) )^(1/3)-1)*100, NA()) | H16: =IFERROR(INDEX(Crude_Oil_Impact!$H:$H, MATCH($A16, Crude_Oil_Impact!$A:$A, 0)), NA()) | I16: =IFERROR(INDEX(REER_Data!$C:$C, MATCH($A16, REER_Data!$A:$A, 0)), NA()) | J16: =IFERROR(INDEX(REER_Data!$E:$E, MATCH($A16, REER_Data!$A:$A, 0)) / 100, NA()) | K16: NA() | M16: 1443256000000 | N16: =IFERROR(1*INDEX(CAGR!$H:$H, MATCH($A16&"|"&$B$2, CAGR!$Q:$Q, 0)), NA()) | O16: =IFERROR(1*INDEX(CAGR!$G:$G, MATCH($A16&"|"&$B$2, CAGR!$Q:$Q, 0)), NA()) | Q16: =IFERROR(1*INDEX(CAGR!$J:$J, MATCH($A16&"|"&$B$2, CAGR!$Q:$Q, 0)), NA()) | R16: =IFERROR(1*INDEX(CAGR!$K:$K, MATCH($A16&"|"&$B$2, CAGR!$Q:$Q, 0)), NA()) | S16: 0.87279998 | T16: NA() | V16: =IFERROR(1*INDEX(CAGR!$N:$N, MATCH($A16&"|"&$B$2, CAGR!$Q:$Q, 0)), NA()) | X16: =IF(AND(ISNUMBER(Q16),ISNUMBER(V16)),Q16+V16,NA()) | Z16: Asia | AA16: IDR | AC16: =IFERROR(INDEX(Lists!$J$2:$J$42, MATCH($B16, Lists!$I$2:$I$42, 0)),"") | AD16: =IFERROR(INDEX(Lists!$K$2:$K$42, MATCH($B16, Lists!$I$2:$I$42, 0)),"")
A17: Italy | B17: EWI | C17: =IFERROR(1*INDEX(CAGR!$I:$I, MATCH($A17&"|"&$B$2, CAGR!$Q:$Q, 0)), NA()) | D17: =IFERROR(1*INDEX(CAGR!$F:$F, MATCH($A17&"|"&$B17&"|"&$B$2, CAGR!$P:$P, 0)), NA()) | E17: =IFERROR(INDEX(MSCI!$B:$E, MATCH("Italy", MSCI!$A:$A, 0), MATCH($B$2, MSCI!$B$1:$E$1, 0)), NA()) | F17: =IF(AND(ISNUMBER(C17),ISNUMBER(D17)),C17-D17,NA()) | G17: =IFERROR((( (1+INDEX(Annual!$H:$H, MATCH($A17&"|2026", Annual!$K:$K, 0))/100)*(1+INDEX(Annual!$H:$H, MATCH($A17&"|2027", Annual!$K:$K, 0))/100)*(1+INDEX(Annual!$H:$H, MATCH($A17&"|2028", Annual!$K:$K, 0))/100) )^(1/3)-1)*100, NA()) | H17: =IFERROR(INDEX(Crude_Oil_Impact!$H:$H, MATCH($A17, Crude_Oil_Impact!$A:$A, 0)), NA()) | I17: =IFERROR(INDEX(REER_Data!$C:$C, MATCH($A17, REER_Data!$A:$A, 0)), NA()) | J17: =IFERROR(INDEX(REER_Data!$E:$E, MATCH($A17, REER_Data!$A:$A, 0)) / 100, NA()) | K17: NA() | M17: 2543677000000 | N17: =IFERROR(1*INDEX(CAGR!$H:$H, MATCH($A17&"|"&$B$2, CAGR!$Q:$Q, 0)), NA()) | O17: =IFERROR(1*INDEX(CAGR!$G:$G, MATCH($A17&"|"&$B$2, CAGR!$Q:$Q, 0)), NA()) | Q17: =IFERROR(1*INDEX(CAGR!$J:$J, MATCH($A17&"|"&$B$2, CAGR!$Q:$Q, 0)), NA()) | R17: =IFERROR(1*INDEX(CAGR!$K:$K, MATCH($A17&"|"&$B$2, CAGR!$Q:$Q, 0)), NA()) | S17: 1 | T17: NA() | V17: =IFERROR(1*INDEX(CAGR!$N:$N, MATCH($A17&"|"&$B$2, CAGR!$Q:$Q, 0)), NA()) | X17: =IF(AND(ISNUMBER(Q17),ISNUMBER(V17)),Q17+V17,NA()) | Z17: Europe | AA17: EUR | AC17: =IFERROR(INDEX(Lists!$J$2:$J$42, MATCH($B17, Lists!$I$2:$I$42, 0)),"") | AD17: =IFERROR(INDEX(Lists!$K$2:$K$42, MATCH($B17, Lists!$I$2:$I$42, 0)),"")
A18: Japan | B18: CJPU.L | C18: =IFERROR(1*INDEX(CAGR!$I:$I, MATCH($A18&"|"&$B$2, CAGR!$Q:$Q, 0)), NA()) | D18: =IFERROR(1*INDEX(CAGR!$F:$F, MATCH($A18&"|"&$B18&"|"&$B$2, CAGR!$P:$P, 0)), NA()) | E18: =IFERROR(INDEX(MSCI!$B:$E, MATCH("Japan", MSCI!$A:$A, 0), MATCH($B$2, MSCI!$B$1:$E$1, 0)), NA()) | F18: =IF(AND(ISNUMBER(C18),ISNUMBER(D18)),C18-D18,NA()) | G18: =IFERROR((( (1+INDEX(Annual!$H:$H, MATCH($A18&"|2026", Annual!$K:$K, 0))/100)*(1+INDEX(Annual!$H:$H, MATCH($A18&"|2027", Annual!$K:$K, 0))/100)*(1+INDEX(Annual!$H:$H, MATCH($A18&"|2028", Annual!$K:$K, 0))/100) )^(1/3)-1)*100, NA()) | H18: =IFERROR(INDEX(Crude_Oil_Impact!$H:$H, MATCH($A18, Crude_Oil_Impact!$A:$A, 0)), NA()) | I18: =IFERROR(INDEX(REER_Data!$C:$C, MATCH($A18, REER_Data!$A:$A, 0)), NA()) | J18: =IFERROR(INDEX(REER_Data!$E:$E, MATCH($A18, REER_Data!$A:$A, 0)) / 100, NA()) | K18: NA() | M18: 4279828000000 | N18: =IFERROR(1*INDEX(CAGR!$H:$H, MATCH($A18&"|"&$B$2, CAGR!$Q:$Q, 0)), NA()) | O18: =IFERROR(1*INDEX(CAGR!$G:$G, MATCH($A18&"|"&$B$2, CAGR!$Q:$Q, 0)), NA()) | Q18: =IFERROR(1*INDEX(CAGR!$J:$J, MATCH($A18&"|"&$B$2, CAGR!$Q:$Q, 0)), NA()) | R18: =IFERROR(1*INDEX(CAGR!$K:$K, MATCH($A18&"|"&$B$2, CAGR!$Q:$Q, 0)), NA()) | S18: 1 | T18: NA() | V18: =IFERROR(1*INDEX(CAGR!$N:$N, MATCH($A18&"|"&$B$2, CAGR!$Q:$Q, 0)), NA()) | X18: =IF(AND(ISNUMBER(Q18),ISNUMBER(V18)),Q18+V18,NA()) | Z18: Asia | AA18: JPY | AC18: =IFERROR(INDEX(Lists!$J$2:$J$42, MATCH($B18, Lists!$I$2:$I$42, 0)),"") | AD18: =IFERROR(INDEX(Lists!$K$2:$K$42, MATCH($B18, Lists!$I$2:$I$42, 0)),"")
A19: Malaysia | B19: XCX3.L | C19: =IFERROR(1*INDEX(CAGR!$I:$I, MATCH($A19&"|"&$B$2, CAGR!$Q:$Q, 0)), NA()) | D19: =IFERROR(1*INDEX(CAGR!$F:$F, MATCH($A19&"|"&$B19&"|"&$B$2, CAGR!$P:$P, 0)), NA()) | E19: =IFERROR(INDEX(MSCI!$B:$E, MATCH("Malaysia", MSCI!$A:$A, 0), MATCH($B$2, MSCI!$B$1:$E$1, 0)), NA()) | F19: =IF(AND(ISNUMBER(C19),ISNUMBER(D19)),C19-D19,NA()) | G19: =IFERROR((( (1+INDEX(Annual!$H:$H, MATCH($A19&"|2026", Annual!$K:$K, 0))/100)*(1+INDEX(Annual!$H:$H, MATCH($A19&"|2027", Annual!$K:$K, 0))/100)*(1+INDEX(Annual!$H:$H, MATCH($A19&"|2028", Annual!$K:$K, 0))/100) )^(1/3)-1)*100, NA()) | H19: =IFERROR(INDEX(Crude_Oil_Impact!$H:$H, MATCH($A19, Crude_Oil_Impact!$A:$A, 0)), NA()) | I19: =IFERROR(INDEX(REER_Data!$C:$C, MATCH($A19, REER_Data!$A:$A, 0)), NA()) | J19: =IFERROR(INDEX(REER_Data!$E:$E, MATCH($A19, REER_Data!$A:$A, 0)) / 100, NA()) | K19: NA() | M19: 470572000000 | N19: =IFERROR(1*INDEX(CAGR!$H:$H, MATCH($A19&"|"&$B$2, CAGR!$Q:$Q, 0)), NA()) | O19: =IFERROR(1*INDEX(CAGR!$G:$G, MATCH($A19&"|"&$B$2, CAGR!$Q:$Q, 0)), NA()) | Q19: =IFERROR(1*INDEX(CAGR!$J:$J, MATCH($A19&"|"&$B$2, CAGR!$Q:$Q, 0)), NA()) | R19: =IFERROR(1*INDEX(CAGR!$K:$K, MATCH($A19&"|"&$B$2, CAGR!$Q:$Q, 0)), NA()) | T19: NA() | V19: =IFERROR(1*INDEX(CAGR!$N:$N, MATCH($A19&"|"&$B$2, CAGR!$Q:$Q, 0)), NA()) | X19: =IF(AND(ISNUMBER(Q19),ISNUMBER(V19)),Q19+V19,NA()) | Z19: Asia | AA19: MYR | AC19: =IFERROR(INDEX(Lists!$J$2:$J$42, MATCH($B19, Lists!$I$2:$I$42, 0)),"") | AD19: =IFERROR(INDEX(Lists!$K$2:$K$42, MATCH($B19, Lists!$I$2:$I$42, 0)),"")
A20: Mexico | B20: XMEX.L | C20: =IFERROR(1*INDEX(CAGR!$I:$I, MATCH($A20&"|"&$B$2, CAGR!$Q:$Q, 0)), NA()) | D20: =IFERROR(1*INDEX(CAGR!$F:$F, MATCH($A20&"|"&$B20&"|"&$B$2, CAGR!$P:$P, 0)), NA()) | E20: =IFERROR(INDEX(MSCI!$B:$E, MATCH("Mexico", MSCI!$A:$A, 0), MATCH($B$2, MSCI!$B$1:$E$1, 0)), NA()) | F20: =IF(AND(ISNUMBER(C20),ISNUMBER(D20)),C20-D20,NA()) | G20: =IFERROR((( (1+INDEX(Annual!$H:$H, MATCH($A20&"|2026", Annual!$K:$K, 0))/100)*(1+INDEX(Annual!$H:$H, MATCH($A20&"|2027", Annual!$K:$K, 0))/100)*(1+INDEX(Annual!$H:$H, MATCH($A20&"|2028", Annual!$K:$K, 0))/100) )^(1/3)-1)*100, NA()) | H20: =IFERROR(INDEX(Crude_Oil_Impact!$H:$H, MATCH($A20, Crude_Oil_Impact!$A:$A, 0)), NA()) | I20: =IFERROR(INDEX(REER_Data!$C:$C, MATCH($A20, REER_Data!$A:$A, 0)), NA()) | J20: =IFERROR(INDEX(REER_Data!$E:$E, MATCH($A20, REER_Data!$A:$A, 0)) / 100, NA()) | K20: NA() | M20: 1862740000000 | N20: =IFERROR(1*INDEX(CAGR!$H:$H, MATCH($A20&"|"&$B$2, CAGR!$Q:$Q, 0)), NA()) | O20: =IFERROR(1*INDEX(CAGR!$G:$G, MATCH($A20&"|"&$B$2, CAGR!$Q:$Q, 0)), NA()) | Q20: =IFERROR(1*INDEX(CAGR!$J:$J, MATCH($A20&"|"&$B$2, CAGR!$Q:$Q, 0)), NA()) | R20: =IFERROR(1*INDEX(CAGR!$K:$K, MATCH($A20&"|"&$B$2, CAGR!$Q:$Q, 0)), NA()) | T20: NA() | V20: =IFERROR(1*INDEX(CAGR!$N:$N, MATCH($A20&"|"&$B$2, CAGR!$Q:$Q, 0)), NA()) | X20: =IF(AND(ISNUMBER(Q20),ISNUMBER(V20)),Q20+V20,NA()) | Z20: Latin America | AA20: MXN | AC20: =IFERROR(INDEX(Lists!$J$2:$J$42, MATCH($B20, Lists!$I$2:$I$42, 0)),"") | AD20: =IFERROR(INDEX(Lists!$K$2:$K$42, MATCH($B20, Lists!$I$2:$I$42, 0)),"")
A21: Netherlands | B21: EWN | C21: =IFERROR(1*INDEX(CAGR!$I:$I, MATCH($A21&"|"&$B$2, CAGR!$Q:$Q, 0)), NA()) | D21: =IFERROR(1*INDEX(CAGR!$F:$F, MATCH($A21&"|"&$B21&"|"&$B$2, CAGR!$P:$P, 0)), NA()) | E21: =IFERROR(INDEX(MSCI!$B:$E, MATCH("Netherlands", MSCI!$A:$A, 0), MATCH($B$2, MSCI!$B$1:$E$1, 0)), NA()) | F21: =IF(AND(ISNUMBER(C21),ISNUMBER(D21)),C21-D21,NA()) | G21: =IFERROR((( (1+INDEX(Annual!$H:$H, MATCH($A21&"|2026", Annual!$K:$K, 0))/100)*(1+INDEX(Annual!$H:$H, MATCH($A21&"|2027", Annual!$K:$K, 0))/100)*(1+INDEX(Annual!$H:$H, MATCH($A21&"|2028", Annual!$K:$K, 0))/100) )^(1/3)-1)*100, NA()) | H21: =IFERROR(INDEX(Crude_Oil_Impact!$H:$H, MATCH($A21, Crude_Oil_Impact!$A:$A, 0)), NA()) | I21: =IFERROR(INDEX(REER_Data!$C:$C, MATCH($A21, REER_Data!$A:$A, 0)), NA()) | J21: =IFERROR(INDEX(REER_Data!$E:$E, MATCH($A21, REER_Data!$A:$A, 0)) / 100, NA()) | K21: NA() | M21: 1320635000000 | N21: =IFERROR(1*INDEX(CAGR!$H:$H, MATCH($A21&"|"&$B$2, CAGR!$Q:$Q, 0)), NA()) | O21: =IFERROR(1*INDEX(CAGR!$G:$G, MATCH($A21&"|"&$B$2, CAGR!$Q:$Q, 0)), NA()) | Q21: =IFERROR(1*INDEX(CAGR!$J:$J, MATCH($A21&"|"&$B$2, CAGR!$Q:$Q, 0)), NA()) | R21: =IFERROR(1*INDEX(CAGR!$K:$K, MATCH($A21&"|"&$B$2, CAGR!$Q:$Q, 0)), NA()) | S21: 1 | T21: NA() | V21: =IFERROR(1*INDEX(CAGR!$N:$N, MATCH($A21&"|"&$B$2, CAGR!$Q:$Q, 0)), NA()) | X21: =IF(AND(ISNUMBER(Q21),ISNUMBER(V21)),Q21+V21,NA()) | Z21: Europe | AA21: EUR | AC21: =IFERROR(INDEX(Lists!$J$2:$J$42, MATCH($B21, Lists!$I$2:$I$42, 0)),"") | AD21: =IFERROR(INDEX(Lists!$K$2:$K$42, MATCH($B21, Lists!$I$2:$I$42, 0)),"")
A22: Pakistan | B22: XBAK.L | C22: =IFERROR(1*INDEX(CAGR!$I:$I, MATCH($A22&"|"&$B$2, CAGR!$Q:$Q, 0)), NA()) | D22: =IFERROR(1*INDEX(CAGR!$F:$F, MATCH($A22&"|"&$B22&"|"&$B$2, CAGR!$P:$P, 0)), NA()) | E22: =IFERROR(INDEX(MSCI!$B:$E, MATCH("Pakistan", MSCI!$A:$A, 0), MATCH($B$2, MSCI!$B$1:$E$1, 0)), NA()) | F22: =IF(AND(ISNUMBER(C22),ISNUMBER(D22)),C22-D22,NA()) | G22: =IFERROR((( (1+INDEX(Annual!$H:$H, MATCH($A22&"|2026", Annual!$K:$K, 0))/100)*(1+INDEX(Annual!$H:$H, MATCH($A22&"|2027", Annual!$K:$K, 0))/100)*(1+INDEX(Annual!$H:$H, MATCH($A22&"|2028", Annual!$K:$K, 0))/100) )^(1/3)-1)*100, NA()) | H22: =IFERROR(INDEX(Crude_Oil_Impact!$H:$H, MATCH($A22, Crude_Oil_Impact!$A:$A, 0)), NA()) | I22: =IFERROR(INDEX(REER_Data!$C:$C, MATCH($A22, REER_Data!$A:$A, 0)), NA()) | J22: =IFERROR(INDEX(REER_Data!$E:$E, MATCH($A22, REER_Data!$A:$A, 0)) / 100, NA()) | K22: NA() | M22: 410495000000 | N22: =IFERROR(1*INDEX(CAGR!$H:$H, MATCH($A22&"|"&$B$2, CAGR!$Q:$Q, 0)), NA()) | O22: =IFERROR(1*INDEX(CAGR!$G:$G, MATCH($A22&"|"&$B$2, CAGR!$Q:$Q, 0)), NA()) | Q22: =IFERROR(1*INDEX(CAGR!$J:$J, MATCH($A22&"|"&$B$2, CAGR!$Q:$Q, 0)), NA()) | R22: =IFERROR(1*INDEX(CAGR!$K:$K, MATCH($A22&"|"&$B$2, CAGR!$Q:$Q, 0)), NA()) | S22: 1 | T22: NA() | V22: =IFERROR(1*INDEX(CAGR!$N:$N, MATCH($A22&"|"&$B$2, CAGR!$Q:$Q, 0)), NA()) | X22: =IF(AND(ISNUMBER(Q22),ISNUMBER(V22)),Q22+V22,NA()) | Z22: Asia | AA22: PKR | AC22: =IFERROR(INDEX(Lists!$J$2:$J$42, MATCH($B22, Lists!$I$2:$I$42, 0)),"") | AD22: =IFERROR(INDEX(Lists!$K$2:$K$42, MATCH($B22, Lists!$I$2:$I$42, 0)),"")
